Workbook

Sheet START HERE
A1: FAFO CLAN INTEL · FUCT against the field
A2: One source of truth, ten ways to slice it. FUCT is the focal point throughout.
B4: =COUNTA(MASTER!$C$4:$C$1463)&" players · 14 clans · "&COUNTIF(MASTER!$S:$S,"Complete")&" fully scouted · "&COUNTIF(MASTER!$I:$I,">=10000")&" in the 10k+ club" -> 1360 players · 14 clans · 1324 fully scouted · 55 in the 10k+ club
B7: WHERE TO GO
B8: =HYPERLINK("#'DASHBOARD'!A1","▶ DASHBOARD") -> ▶ DASHBOARD | C8: All fourteen clans with a Shadow / Immortal switch. Scoreboard, tier and class spread, a vs-FUCT column and a chart.
B9: =HYPERLINK("#'DEPTH CURVES'!A1","▶ DEPTH CURVES") -> ▶ DEPTH CURVES | C9: The line graph: every clan ranked 1st to 100th by Reso. Shows exactly which slice of a roster beats ours.
B10: =HYPERLINK("#'LEADERBOARDS'!A1","▶ LEADERBOARDS") -> ▶ LEADERBOARDS | C10: Top 30 by Resonance, Combat Rating and Power Index, plus every clan podium. FUCT rows highlighted.
B11: =HYPERLINK("#'TIER BOARDS'!A1","▶ TIER BOARDS") -> ▶ TIER BOARDS | C11: Six cross-tab matrices — Reso tier, class, CR band, secondary tier, role and data status — against all fourteen clans.
B12: =HYPERLINK("#'PLAYER CARD'!A1","▶ PLAYER CARD") -> ▶ PLAYER CARD | C12: Pick any of the 1,361 names from an alphabetical dropdown. Full stat line, ranks, clan and field comparison, rivals, class ladder.
B13: =HYPERLINK("#'CLAN COMPARE'!A1","▶ CLAN COMPARE") -> ▶ CLAN COMPARE | C13: FUCT against anyone, fifteen metrics head to head, with the stronger side marked.
B14: =HYPERLINK("#'WARBANDS'!A1","▶ WARBANDS") -> ▶ WARBANDS | C14: Warband summary plus a picker showing all twelve slots of whichever one you choose, open seats included.
B15: =HYPERLINK("#'TRANSFERS'!A1","▶ TRANSFERS") -> ▶ TRANSFERS | C15: The rollout plan — who is approved, staying or requested, and where they are headed.
B16: =HYPERLINK("#'MASTER'!A1","▶ MASTER") -> ▶ MASTER | C16: Every player, every stat, filterable. The only tab you type into for roster data.
B17: =HYPERLINK("#'SETUP'!A1","▶ SETUP") -> ▶ SETUP | C17: Tier thresholds, Power Index weights, the class-to-role map and the faction map. Change a number, the book re-cuts.
B19: THE CLAN TABS · gold is us (standalone), red is Immortal, purple is Shadow
B20: =HYPERLINK("#'FUCT'!A1","▶ FUCT") -> ▶ FUCT | C20: ="standalone · "&COUNTIF(MASTER!$B:$B,"FUCT")&" members · "&COUNTIFS(MASTER!$B:$B,"FUCT",MASTER!$S:$S,"Complete")&" scouted · "&IF(COUNTIFS(MASTER!$B:$B,"FUCT",MASTER!$S:$S,"Complete")=0,"no stats yet","avg Reso "&TEXT(IFERROR(AVERAGEIFS(MASTER!$I:$I,MASTER!$B:$B,"FUCT"),0),"#,##0"))&" · top: "&IFERROR(INDEX(MASTER!$C:$C,MATCH("FUCT"&"|1",MASTER!$Y:$Y,0)),"-") -> standalone · 99 members · 99 scouted · avg Reso 5,214 · top: Wulf
B21: =HYPERLINK("#'LEGENDS'!A1","▶ LEGENDS") -> ▶ LEGENDS | C21: ="immortal · "&COUNTIF(MASTER!$B:$B,"LEGENDS")&" members · "&COUNTIFS(MASTER!$B:$B,"LEGENDS",MASTER!$S:$S,"Complete")&" scouted · "&IF(COUNTIFS(MASTER!$B:$B,"LEGENDS",MASTER!$S:$S,"Complete")=0,"no stats yet","avg Reso "&TEXT(IFERROR(AVERAGEIFS(MASTER!$I:$I,MASTER!$B:$B,"LEGENDS"),0),"#,##0"))&" · top: "&IFERROR(INDEX(MASTER!$C:$C,MATCH("LEGENDS"&"|1",MASTER!$Y:$Y,0)),"-") -> immortal · 100 members · 97 scouted · avg Reso 5,539 · top: Deeds
B22: =HYPERLINK("#'VANGUARD'!A1","▶ VANGUARD") -> ▶ VANGUARD | C22: ="immortal · "&COUNTIF(MASTER!$B:$B,"VANGUARD")&" members · "&COUNTIFS(MASTER!$B:$B,"VANGUARD",MASTER!$S:$S,"Complete")&" scouted · "&IF(COUNTIFS(MASTER!$B:$B,"VANGUARD",MASTER!$S:$S,"Complete")=0,"no stats yet","avg Reso "&TEXT(IFERROR(AVERAGEIFS(MASTER!$I:$I,MASTER!$B:$B,"VANGUARD"),0),"#,##0"))&" · top: "&IFERROR(INDEX(MASTER!$C:$C,MATCH("VANGUARD"&"|1",MASTER!$Y:$Y,0)),"-") -> immortal · 95 members · 95 scouted · avg Reso 6,666 · top: Orionpax
B23: =HYPERLINK("#'UNDYING'!A1","▶ UNDYING") -> ▶ UNDYING | C23: ="immortal · "&COUNTIF(MASTER!$B:$B,"UNDYING")&" members · "&COUNTIFS(MASTER!$B:$B,"UNDYING",MASTER!$S:$S,"Complete")&" scouted · "&IF(COUNTIFS(MASTER!$B:$B,"UNDYING",MASTER!$S:$S,"Complete")=0,"no stats yet","avg Reso "&TEXT(IFERROR(AVERAGEIFS(MASTER!$I:$I,MASTER!$B:$B,"UNDYING"),0),"#,##0"))&" · top: "&IFERROR(INDEX(MASTER!$C:$C,MATCH("UNDYING"&"|1",MASTER!$Y:$Y,0)),"-") -> immortal · 96 members · 96 scouted · avg Reso 4,582 · top: BOR- Zeroth
B24: =HYPERLINK("#'SBG'!A1","▶ SBG") -> ▶ SBG | C24: ="shadow · "&COUNTIF(MASTER!$B:$B,"SBG")&" members · "&COUNTIFS(MASTER!$B:$B,"SBG",MASTER!$S:$S,"Complete")&" scouted · "&IF(COUNTIFS(MASTER!$B:$B,"SBG",MASTER!$S:$S,"Complete")=0,"no stats yet","avg Reso "&TEXT(IFERROR(AVERAGEIFS(MASTER!$I:$I,MASTER!$B:$B,"SBG"),0),"#,##0"))&" · top: "&IFERROR(INDEX(MASTER!$C:$C,MATCH("SBG"&"|1",MASTER!$Y:$Y,0)),"-") -> shadow · 97 members · 97 scouted · avg Reso 6,056 · top: Solorin
B25: =HYPERLINK("#'AZUKI'!A1","▶ AZUKI") -> ▶ AZUKI | C25: ="shadow · "&COUNTIF(MASTER!$B:$B,"AZUKI")&" members · "&COUNTIFS(MASTER!$B:$B,"AZUKI",MASTER!$S:$S,"Complete")&" scouted · "&IF(COUNTIFS(MASTER!$B:$B,"AZUKI",MASTER!$S:$S,"Complete")=0,"no stats yet","avg Reso "&TEXT(IFERROR(AVERAGEIFS(MASTER!$I:$I,MASTER!$B:$B,"AZUKI"),0),"#,##0"))&" · top: "&IFERROR(INDEX(MASTER!$C:$C,MATCH("AZUKI"&"|1",MASTER!$Y:$Y,0)),"-") -> shadow · 102 members · 101 scouted · avg Reso 5,754 · top: AMBER
B26: =HYPERLINK("#'RECKONING'!A1","▶ RECKONING") -> ▶ RECKONING | C26: ="shadow · "&COUNTIF(MASTER!$B:$B,"RECKONING")&" members · "&COUNTIFS(MASTER!$B:$B,"RECKONING",MASTER!$S:$S,"Complete")&" scouted · "&IF(COUNTIFS(MASTER!$B:$B,"RECKONING",MASTER!$S:$S,"Complete")=0,"no stats yet","avg Reso "&TEXT(IFERROR(AVERAGEIFS(MASTER!$I:$I,MASTER!$B:$B,"RECKONING"),0),"#,##0"))&" · top: "&IFERROR(INDEX(MASTER!$C:$C,MATCH("RECKONING"&"|1",MASTER!$Y:$Y,0)),"-") -> shadow · 97 members · 97 scouted · avg Reso 5,541 · top: Rydog
B27: =HYPERLINK("#'ACHERON'!A1","▶ ACHERON") -> ▶ ACHERON | C27: ="shadow · "&COUNTIF(MASTER!$B:$B,"ACHERON")&" members · "&COUNTIFS(MASTER!$B:$B,"ACHERON",MASTER!$S:$S,"Complete")&" scouted · "&IF(COUNTIFS(MASTER!$B:$B,"ACHERON",MASTER!$S:$S,"Complete")=0,"no stats yet","avg Reso "&TEXT(IFERROR(AVERAGEIFS(MASTER!$I:$I,MASTER!$B:$B,"ACHERON"),0),"#,##0"))&" · top: "&IFERROR(INDEX(MASTER!$C:$C,MATCH("ACHERON"&"|1",MASTER!$Y:$Y,0)),"-") -> shadow · 96 members · 94 scouted · avg Reso 4,133 · top: Sölus
B28: =HYPERLINK("#'INVICTUS'!A1","▶ INVICTUS") -> ▶ INVICTUS | C28: ="shadow · "&COUNTIF(MASTER!$B:$B,"INVICTUS")&" members · "&COUNTIFS(MASTER!$B:$B,"INVICTUS",MASTER!$S:$S,"Complete")&" scouted · "&IF(COUNTIFS(MASTER!$B:$B,"INVICTUS",MASTER!$S:$S,"Complete")=0,"no stats yet","avg Reso "&TEXT(IFERROR(AVERAGEIFS(MASTER!$I:$I,MASTER!$B:$B,"INVICTUS"),0),"#,##0"))&" · top: "&IFERROR(INDEX(MASTER!$C:$C,MATCH("INVICTUS"&"|1",MASTER!$Y:$Y,0)),"-") -> shadow · 100 members · 99 scouted · avg Reso 3,415 · top: Seric
B29: =HYPERLINK("#'EMERALD LEAF'!A1","▶ EMERALD LEAF TRIBE") -> ▶ EMERALD LEAF TRIBE | C29: ="shadow · "&COUNTIF(MASTER!$B:$B,"EMERALD LEAF TRIBE")&" members · "&COUNTIFS(MASTER!$B:$B,"EMERALD LEAF TRIBE",MASTER!$S:$S,"Complete")&" scouted · "&IF(COUNTIFS(MASTER!$B:$B,"EMERALD LEAF TRIBE",MASTER!$S:$S,"Complete")=0,"no stats yet","avg Reso "&TEXT(IFERROR(AVERAGEIFS(MASTER!$I:$I,MASTER!$B:$B,"EMERALD LEAF TRIBE"),0),"#,##0"))&" · top: "&IFERROR(INDEX(MASTER!$C:$C,MATCH("EMERALD LEAF TRIBE"&"|1",MASTER!$Y:$Y,0)),"-") -> shadow · 97 members · 97 scouted · avg Reso 2,318 · top: Cal66
B30: =HYPERLINK("#'SUB ROSA'!A1","▶ SUB ROSA") -> ▶ SUB ROSA | C30: ="shadow · "&COUNTIF(MASTER!$B:$B,"SUB ROSA")&" members · "&COUNTIFS(MASTER!$B:$B,"SUB ROSA",MASTER!$S:$S,"Complete")&" scouted · "&IF(COUNTIFS(MASTER!$B:$B,"SUB ROSA",MASTER!$S:$S,"Complete")=0,"no stats yet","avg Reso "&TEXT(IFERROR(AVERAGEIFS(MASTER!$I:$I,MASTER!$B:$B,"SUB ROSA"),0),"#,##0"))&" · top: "&IFERROR(INDEX(MASTER!$C:$C,MATCH("SUB ROSA"&"|1",MASTER!$Y:$Y,0)),"-") -> shadow · 93 members · 68 scouted · avg Reso 3,056 · top: Dwai
B31: =HYPERLINK("#'VENGEANCE'!A1","▶ VENGEANCE") -> ▶ VENGEANCE | C31: ="shadow · "&COUNTIF(MASTER!$B:$B,"VENGEANCE")&" members · "&COUNTIFS(MASTER!$B:$B,"VENGEANCE",MASTER!$S:$S,"Complete")&" scouted · "&IF(COUNTIFS(MASTER!$B:$B,"VENGEANCE",MASTER!$S:$S,"Complete")=0,"no stats yet","avg Reso "&TEXT(IFERROR(AVERAGEIFS(MASTER!$I:$I,MASTER!$B:$B,"VENGEANCE"),0),"#,##0"))&" · top: "&IFERROR(INDEX(MASTER!$C:$C,MATCH("VENGEANCE"&"|1",MASTER!$Y:$Y,0)),"-") -> shadow · 96 members · 94 scouted · avg Reso 3,603 · top: Stevo77
B32: =HYPERLINK("#'VENDETTA'!A1","▶ VENDETTA") -> ▶ VENDETTA | C32: ="shadow · "&COUNTIF(MASTER!$B:$B,"VENDETTA")&" members · "&COUNTIFS(MASTER!$B:$B,"VENDETTA",MASTER!$S:$S,"Complete")&" scouted · "&IF(COUNTIFS(MASTER!$B:$B,"VENDETTA",MASTER!$S:$S,"Complete")=0,"no stats yet","avg Reso "&TEXT(IFERROR(AVERAGEIFS(MASTER!$I:$I,MASTER!$B:$B,"VENDETTA"),0),"#,##0"))&" · top: "&IFERROR(INDEX(MASTER!$C:$C,MATCH("VENDETTA"&"|1",MASTER!$Y:$Y,0)),"-") -> shadow · 94 members · 93 scouted · avg Reso 2,098 · top: anamal
B33: =HYPERLINK("#'ZOMBIES'!A1","▶ ZOMBIES") -> ▶ ZOMBIES | C33: ="shadow · "&COUNTIF(MASTER!$B:$B,"ZOMBIES")&" members · "&COUNTIFS(MASTER!$B:$B,"ZOMBIES",MASTER!$S:$S,"Complete")&" scouted · "&IF(COUNTIFS(MASTER!$B:$B,"ZOMBIES",MASTER!$S:$S,"Complete")=0,"no stats yet","avg Reso "&TEXT(IFERROR(AVERAGEIFS(MASTER!$I:$I,MASTER!$B:$B,"ZOMBIES"),0),"#,##0"))&" · top: "&IFERROR(INDEX(MASTER!$C:$C,MATCH("ZOMBIES"&"|1",MASTER!$Y:$Y,0)),"-") -> shadow · 98 members · 97 scouted · avg Reso 2,100 · top: THERIDDIC
B35: HOW IT WORKS
B36: One place to type | C36: MASTER is the source. Cream cells are yours. Every other cell in the workbook is a formula pointing back at it. Clan, faction and class are dropdowns so a typo cannot quietly drop someone out of the counts.
B37: Adding a player | C37: Type into the first empty row at the bottom of MASTER — the formulas are already built into the next 100 rows, so a new player flows through to their clan tab, the leaderboards, the matrices and the charts with no dragging.
B38: Rosters are alphabetical | C38: Every clan tab lists members A to Z, with their Reso rank alongside. Leaderboards stay ranked by value, since that is their whole point.
B39: The faction switch | C39: The dropdown at the top of DASHBOARD filters to Shadow, Immortal, Standalone or everything. FUCT stays pinned in view whichever you pick, because it is the thing everything else is measured against.
B40: Power Index | C40: A blended 0-100 score: 55% Reso, 25% Combat Rating, 20% secondary, each against a benchmark on SETUP. The weighting is a judgement call and is editable.
B41: Secondaries | C41: One combined average per player, covering whatever secondaries were recorded — usually two of the four. Original text is preserved in hidden column AF on MASTER.
B42: Nothing was deleted | C42: Every original value is here. Suspect entries are flagged in the Flags column on MASTER, never overwritten.
B44: Built from FAFO_12-08-2025 (3).xlsx · fishing, EAST COAST, HUNT FOR THREE, GEM LEVELS and the Resonance Source tabs were left alone.

Sheet DASHBOARD
A1: DASHBOARD · fourteen clans
A2: FUCT is standalone — no faction. Flip the switch to look at Shadow, Immortal, or everything. FUCT stays visible throughout.
A3: SHOW > | C3: ALL | E3: < faction switch. Everything below follows it — FUCT stays in view either way, since it is the comparison.
A6: PLAYERS IN VIEW | C6: CLANS IN VIEW | E6: AVG RESO | G6: FUCT AVG RESO | I6: FUCT RANK BY AVG RESO | K6: 10K+ IN VIEW | M6: FUCT 10K+ CLUB | O6: TOP PLAYER IN VIEW
A7: =SUMPRODUCT((MASTER!$C$4:$C$1463<>"")*(IF($C$3="ALL",1,MASTER!$A$4:$A$1463=$C$3))) -> 1360 | C7: =COUNT(SETUP!$E$68:$E$81) -> 14 | E7: =IFERROR(ROUND(IF($C$3="ALL",AVERAGE(MASTER!$I$4:$I$1463),AVERAGEIF(MASTER!$A$4:$A$1463,$C$3,MASTER!$I$4:$I$1463)),0),"-") -> 4326 | G7: =IFERROR(ROUND(AVERAGEIF(MASTER!$B:$B,"FUCT",MASTER!$I:$I),0),"-") -> 5214 | I7: =IFERROR(RANK(INDEX($G$11:$G$24,MATCH("FUCT",$A$11:$A$24,0)),$G$11:$G$24)&" of "&COUNT($G$11:$G$24),"-") -> 6 of 14 | K7: =SUMPRODUCT((MASTER!$I$4:$I$1463>=10000)*(IF($C$3="ALL",1,MASTER!$A$4:$A$1463=$C$3))) -> 55 | M7: =COUNTIFS(MASTER!$B:$B,"FUCT",MASTER!$I:$I,">=10000") -> 5 | O7: =IFERROR(INDEX($P$11:$P$24,MATCH(MAX($H$11:$H$24),$H$11:$H$24,0)),"-") -> AMBER
A9: CLAN SCOREBOARD · sorted by the faction switch, FUCT highlighted
A10: Clan | B10: Faction | C10: Members | D10: Scouted | E10: Avg CR | F10: Best CR | G10: Avg Reso | H10: Best Reso | I10: Median Reso | J10: 10k+ | K10: 8k-10k | L10: Avg Sec (k) | M10: Avg Power | N10: vs FUCT avg reso | O10: Power rank | P10: Top player | Q10: Their reso
A11: =IFERROR(INDEX(SETUP!$A$68:$A$81,MATCH(1,SETUP!$E$68:$E$81,0)),"") -> FUCT | B11: =IF($A11="","",IFERROR(INDEX(SETUP!$B$68:$B$81,MATCH($A11,SETUP!$A$68:$A$81,0)),"-")) -> STANDALONE | C11: =IF($A11="","",COUNTIF(MASTER!$B:$B,$A11)) -> 99 | D11: =IF($A11="","",COUNTIFS(MASTER!$B:$B,$A11,MASTER!$S:$S,"Complete")) -> 99 | E11: =IF($A11="","",IFERROR(ROUND(AVERAGEIFS(MASTER!$G:$G,MASTER!$B:$B,$A11),0),"-")) -> 62784 | F11: =IF($A11="","",IFERROR(_xlfn.MAXIFS(MASTER!$G:$G,MASTER!$B:$B,$A11),"-")) -> 64415 | G11: =IF($A11="","",IFERROR(ROUND(AVERAGEIFS(MASTER!$I:$I,MASTER!$B:$B,$A11),0),"-")) -> 5214 | H11: =IF($A11="","",IFERROR(_xlfn.MAXIFS(MASTER!$I:$I,MASTER!$B:$B,$A11),"-")) -> 11602 | I11: =IF($A11="","",IFERROR(IF(INDEX(MASTER!$I$4:$I$1463,MATCH($A11&"|"&ROUND($C11/2,0),MASTER!$Y$4:$Y$1463,0))="","-",INDEX(MASTER!$I$4:$I$1463,MATCH($A11&"|"&ROUND($C11/2,0),MASTER!$Y$4:$Y$1463,0))),"-")) -> 4435 | J11: =IF($A11="","",COUNTIFS(MASTER!$B:$B,$A11,MASTER!$I:$I,">=10000")) -> 5 | K11: =IF($A11="","",COUNTIFS(MASTER!$B:$B,$A11,MASTER!$I:$I,">=8000",MASTER!$I:$I,"<10000")) -> 9 | L11: =IF($A11="","",IFERROR(ROUND(AVERAGEIFS(MASTER!$L:$L,MASTER!$B:$B,$A11),1),"-")) -> 5.1 | M11: =IF($A11="","",IFERROR(ROUND(AVERAGEIFS(MASTER!$N:$N,MASTER!$B:$B,$A11),1),"-")) -> 51.7 | N11: =IF($A11="","",IFERROR(IF($A11="FUCT","- ours -",$G11-ROUND(AVERAGEIF(MASTER!$B:$B,"FUCT",MASTER!$I:$I),0)),"-")) -> - ours - | O11: =IF(ISNUMBER($M11),RANK($M11,$M$11:$M$24),"-") -> 6 | P11: =IF($A11="","",IFERROR(IF(INDEX(MASTER!$C$4:$C$1463,MATCH($A11&"|1",MASTER!$Y$4:$Y$1463,0))="","-",INDEX(MASTER!$C$4:$C$1463,MATCH($A11&"|1",MASTER!$Y$4:$Y$1463,0))),"-")) -> Wulf | Q11: =IF($A11="","",IFERROR(IF(INDEX(MASTER!$I$4:$I$1463,MATCH($A11&"|1",MASTER!$Y$4:$Y$1463,0))="","-",INDEX(MASTER!$I$4:$I$1463,MATCH($A11&"|1",MASTER!$Y$4:$Y$1463,0))),"-")) -> 11602
A12: =IFERROR(INDEX(SETUP!$A$68:$A$81,MATCH(2,SETUP!$E$68:$E$81,0)),"") -> LEGENDS | B12: =IF($A12="","",IFERROR(INDEX(SETUP!$B$68:$B$81,MATCH($A12,SETUP!$A$68:$A$81,0)),"-")) -> IMMORTAL | C12: =IF($A12="","",COUNTIF(MASTER!$B:$B,$A12)) -> 100 | D12: =IF($A12="","",COUNTIFS(MASTER!$B:$B,$A12,MASTER!$S:$S,"Complete")) -> 97 | E12: =IF($A12="","",IFERROR(ROUND(AVERAGEIFS(MASTER!$G:$G,MASTER!$B:$B,$A12),0),"-")) -> 62868 | F12: =IF($A12="","",IFERROR(_xlfn.MAXIFS(MASTER!$G:$G,MASTER!$B:$B,$A12),"-")) -> 64418 | G12: =IF($A12="","",IFERROR(ROUND(AVERAGEIFS(MASTER!$I:$I,MASTER!$B:$B,$A12),0),"-")) -> 5539 | H12: =IF($A12="","",IFERROR(_xlfn.MAXIFS(MASTER!$I:$I,MASTER!$B:$B,$A12),"-")) -> 11601 | I12: =IF($A12="","",IFERROR(IF(INDEX(MASTER!$I$4:$I$1463,MATCH($A12&"|"&ROUND($C12/2,0),MASTER!$Y$4:$Y$1463,0))="","-",INDEX(MASTER!$I$4:$I$1463,MATCH($A12&"|"&ROUND($C12/2,0),MASTER!$Y$4:$Y$1463,0))),"-")) -> 5093 | J12: =IF($A12="","",COUNTIFS(MASTER!$B:$B,$A12,MASTER!$I:$I,">=10000")) -> 6 | K12: =IF($A12="","",COUNTIFS(MASTER!$B:$B,$A12,MASTER!$I:$I,">=8000",MASTER!$I:$I,"<10000")) -> 6 | L12: =IF($A12="","",IFERROR(ROUND(AVERAGEIFS(MASTER!$L:$L,MASTER!$B:$B,$A12),1),"-")) -> 5.3 | M12: =IF($A12="","",IFERROR(ROUND(AVERAGEIFS(MASTER!$N:$N,MASTER!$B:$B,$A12),1),"-")) -> 53.7 | N12: =IF($A12="","",IFERROR(IF($A12="FUCT","- ours -",$G12-ROUND(AVERAGEIF(MASTER!$B:$B,"FUCT",MASTER!$I:$I),0)),"-")) -> 325 | O12: =IF(ISNUMBER($M12),RANK($M12,$M$11:$M$24),"-") -> 5 | P12: =IF($A12="","",IFERROR(IF(INDEX(MASTER!$C$4:$C$1463,MATCH($A12&"|1",MASTER!$Y$4:$Y$1463,0))="","-",INDEX(MASTER!$C$4:$C$1463,MATCH($A12&"|1",MASTER!$Y$4:$Y$1463,0))),"-")) -> Deeds | Q12: =IF($A12="","",IFERROR(IF(INDEX(MASTER!$I$4:$I$1463,MATCH($A12&"|1",MASTER!$Y$4:$Y$1463,0))="","-",INDEX(MASTER!$I$4:$I$1463,MATCH($A12&"|1",MASTER!$Y$4:$Y$1463,0))),"-")) -> 11601
A13: =IFERROR(INDEX(SETUP!$A$68:$A$81,MATCH(3,SETUP!$E$68:$E$81,0)),"") -> VANGUARD | B13: =IF($A13="","",IFERROR(INDEX(SETUP!$B$68:$B$81,MATCH($A13,SETUP!$A$68:$A$81,0)),"-")) -> IMMORTAL | C13: =IF($A13="","",COUNTIF(MASTER!$B:$B,$A13)) -> 95 | D13: =IF($A13="","",COUNTIFS(MASTER!$B:$B,$A13,MASTER!$S:$S,"Complete")) -> 95 | E13: =IF($A13="","",IFERROR(ROUND(AVERAGEIFS(MASTER!$G:$G,MASTER!$B:$B,$A13),0),"-")) -> 63206 | F13: =IF($A13="","",IFERROR(_xlfn.MAXIFS(MASTER!$G:$G,MASTER!$B:$B,$A13),"-")) -> 64366 | G13: =IF($A13="","",IFERROR(ROUND(AVERAGEIFS(MASTER!$I:$I,MASTER!$B:$B,$A13),0),"-")) -> 6666 | H13: =IF($A13="","",IFERROR(_xlfn.MAXIFS(MASTER!$I:$I,MASTER!$B:$B,$A13),"-")) -> 10905 | I13: =IF($A13="","",IFERROR(IF(INDEX(MASTER!$I$4:$I$1463,MATCH($A13&"|"&ROUND($C13/2,0),MASTER!$Y$4:$Y$1463,0))="","-",INDEX(MASTER!$I$4:$I$1463,MATCH($A13&"|"&ROUND($C13/2,0),MASTER!$Y$4:$Y$1463,0))),"-")) -> 6829 | J13: =IF($A13="","",COUNTIFS(MASTER!$B:$B,$A13,MASTER!$I:$I,">=10000")) -> 10 | K13: =IF($A13="","",COUNTIFS(MASTER!$B:$B,$A13,MASTER!$I:$I,">=8000",MASTER!$I:$I,"<10000")) -> 23 | L13: =IF($A13="","",IFERROR(ROUND(AVERAGEIFS(MASTER!$L:$L,MASTER!$B:$B,$A13),1),"-")) -> 6.1 | M13: =IF($A13="","",IFERROR(ROUND(AVERAGEIFS(MASTER!$N:$N,MASTER!$B:$B,$A13),1),"-")) -> 60.8 | N13: =IF($A13="","",IFERROR(IF($A13="FUCT","- ours -",$G13-ROUND(AVERAGEIF(MASTER!$B:$B,"FUCT",MASTER!$I:$I),0)),"-")) -> 1452 | O13: =IF(ISNUMBER($M13),RANK($M13,$M$11:$M$24),"-") -> 1 | P13: =IF($A13="","",IFERROR(IF(INDEX(MASTER!$C$4:$C$1463,MATCH($A13&"|1",MASTER!$Y$4:$Y$1463,0))="","-",INDEX(MASTER!$C$4:$C$1463,MATCH($A13&"|1",MASTER!$Y$4:$Y$1463,0))),"-")) -> Orionpax | Q13: =IF($A13="","",IFERROR(IF(INDEX(MASTER!$I$4:$I$1463,MATCH($A13&"|1",MASTER!$Y$4:$Y$1463,0))="","-",INDEX(MASTER!$I$4:$I$1463,MATCH($A13&"|1",MASTER!$Y$4:$Y$1463,0))),"-")) -> 10905
A14: =IFERROR(INDEX(SETUP!$A$68:$A$81,MATCH(4,SETUP!$E$68:$E$81,0)),"") -> UNDYING | B14: =IF($A14="","",IFERROR(INDEX(SETUP!$B$68:$B$81,MATCH($A14,SETUP!$A$68:$A$81,0)),"-")) -> IMMORTAL | C14: =IF($A14="","",COUNTIF(MASTER!$B:$B,$A14)) -> 96 | D14: =IF($A14="","",COUNTIFS(MASTER!$B:$B,$A14,MASTER!$S:$S,"Complete")) -> 96 | E14: =IF($A14="","",IFERROR(ROUND(AVERAGEIFS(MASTER!$G:$G,MASTER!$B:$B,$A14),0),"-")) -> 62722 | F14: =IF($A14="","",IFERROR(_xlfn.MAXIFS(MASTER!$G:$G,MASTER!$B:$B,$A14),"-")) -> 64189 | G14: =IF($A14="","",IFERROR(ROUND(AVERAGEIFS(MASTER!$I:$I,MASTER!$B:$B,$A14),0),"-")) -> 4582 | H14: =IF($A14="","",IFERROR(_xlfn.MAXIFS(MASTER!$I:$I,MASTER!$B:$B,$A14),"-")) -> 10023 | I14: =IF($A14="","",IFERROR(IF(INDEX(MASTER!$I$4:$I$1463,MATCH($A14&"|"&ROUND($C14/2,0),MASTER!$Y$4:$Y$1463,0))="","-",INDEX(MASTER!$I$4:$I$1463,MATCH($A14&"|"&ROUND($C14/2,0),MASTER!$Y$4:$Y$1463,0))),"-")) -> 4203 | J14: =IF($A14="","",COUNTIFS(MASTER!$B:$B,$A14,MASTER!$I:$I,">=10000")) -> 1 | K14: =IF($A14="","",COUNTIFS(MASTER!$B:$B,$A14,MASTER!$I:$I,">=8000",MASTER!$I:$I,"<10000")) -> 7 | L14: =IF($A14="","",IFERROR(ROUND(AVERAGEIFS(MASTER!$L:$L,MASTER!$B:$B,$A14),1),"-")) -> 5.3 | M14: =IF($A14="","",IFERROR(ROUND(AVERAGEIFS(MASTER!$N:$N,MASTER!$B:$B,$A14),1),"-")) -> 49.1 | N14: =IF($A14="","",IFERROR(IF($A14="FUCT","- ours -",$G14-ROUND(AVERAGEIF(MASTER!$B:$B,"FUCT",MASTER!$I:$I),0)),"-")) -> -632 | O14: =IF(ISNUMBER($M14),RANK($M14,$M$11:$M$24),"-") -> 7 | P14: =IF($A14="","",IFERROR(IF(INDEX(MASTER!$C$4:$C$1463,MATCH($A14&"|1",MASTER!$Y$4:$Y$1463,0))="","-",INDEX(MASTER!$C$4:$C$1463,MATCH($A14&"|1",MASTER!$Y$4:$Y$1463,0))),"-")) -> BOR- Zeroth | Q14: =IF($A14="","",IFERROR(IF(INDEX(MASTER!$I$4:$I$1463,MATCH($A14&"|1",MASTER!$Y$4:$Y$1463,0))="","-",INDEX(MASTER!$I$4:$I$1463,MATCH($A14&"|1",MASTER!$Y$4:$Y$1463,0))),"-")) -> 10023
A15: =IFERROR(INDEX(SETUP!$A$68:$A$81,MATCH(5,SETUP!$E$68:$E$81,0)),"") -> SBG | B15: =IF($A15="","",IFERROR(INDEX(SETUP!$B$68:$B$81,MATCH($A15,SETUP!$A$68:$A$81,0)),"-")) -> SHADOW | C15: =IF($A15="","",COUNTIF(MASTER!$B:$B,$A15)) -> 97 | D15: =IF($A15="","",COUNTIFS(MASTER!$B:$B,$A15,MASTER!$S:$S,"Complete")) -> 97 | E15: =IF($A15="","",IFERROR(ROUND(AVERAGEIFS(MASTER!$G:$G,MASTER!$B:$B,$A15),0),"-")) -> 62662 | F15: =IF($A15="","",IFERROR(_xlfn.MAXIFS(MASTER!$G:$G,MASTER!$B:$B,$A15),"-")) -> 64351 | G15: =IF($A15="","",IFERROR(ROUND(AVERAGEIFS(MASTER!$I:$I,MASTER!$B:$B,$A15),0),"-")) -> 6056 | H15: =IF($A15="","",IFERROR(_xlfn.MAXIFS(MASTER!$I:$I,MASTER!$B:$B,$A15),"-")) -> 12383 | I15: =IF($A15="","",IFERROR(IF(INDEX(MASTER!$I$4:$I$1463,MATCH($A15&"|"&ROUND($C15/2,0),MASTER!$Y$4:$Y$1463,0))="","-",INDEX(MASTER!$I$4:$I$1463,MATCH($A15&"|"&ROUND($C15/2,0),MASTER!$Y$4:$Y$1463,0))),"-")) -> 5671 | J15: =IF($A15="","",COUNTIFS(MASTER!$B:$B,$A15,MASTER!$I:$I,">=10000")) -> 9 | K15: =IF($A15="","",COUNTIFS(MASTER!$B:$B,$A15,MASTER!$I:$I,">=8000",MASTER!$I:$I,"<10000")) -> 15 | L15: =IF($A15="","",IFERROR(ROUND(AVERAGEIFS(MASTER!$L:$L,MASTER!$B:$B,$A15),1),"-")) -> 6.1 | M15: =IF($A15="","",IFERROR(ROUND(AVERAGEIFS(MASTER!$N:$N,MASTER!$B:$B,$A15),1),"-")) -> 56.7 | N15: =IF($A15="","",IFERROR(IF($A15="FUCT","- ours -",$G15-ROUND(AVERAGEIF(MASTER!$B:$B,"FUCT",MASTER!$I:$I),0)),"-")) -> 842 | O15: =IF(ISNUMBER($M15),RANK($M15,$M$11:$M$24),"-") -> 2 | P15: =IF($A15="","",IFERROR(IF(INDEX(MASTER!$C$4:$C$1463,MATCH($A15&"|1",MASTER!$Y$4:$Y$1463,0))="","-",INDEX(MASTER!$C$4:$C$1463,MATCH($A15&"|1",MASTER!$Y$4:$Y$1463,0))),"-")) -> Solorin | Q15: =IF($A15="","",IFERROR(IF(INDEX(MASTER!$I$4:$I$1463,MATCH($A15&"|1",MASTER!$Y$4:$Y$1463,0))="","-",INDEX(MASTER!$I$4:$I$1463,MATCH($A15&"|1",MASTER!$Y$4:$Y$1463,0))),"-")) -> 12383
A16: =IFERROR(INDEX(SETUP!$A$68:$A$81,MATCH(6,SETUP!$E$68:$E$81,0)),"") -> AZUKI | B16: =IF($A16="","",IFERROR(INDEX(SETUP!$B$68:$B$81,MATCH($A16,SETUP!$A$68:$A$81,0)),"-")) -> SHADOW | C16: =IF($A16="","",COUNTIF(MASTER!$B:$B,$A16)) -> 102 | D16: =IF($A16="","",COUNTIFS(MASTER!$B:$B,$A16,MASTER!$S:$S,"Complete")) -> 101 | E16: =IF($A16="","",IFERROR(ROUND(AVERAGEIFS(MASTER!$G:$G,MASTER!$B:$B,$A16),0),"-")) -> 62696 | F16: =IF($A16="","",IFERROR(_xlfn.MAXIFS(MASTER!$G:$G,MASTER!$B:$B,$A16),"-")) -> 64467 | G16: =IF($A16="","",IFERROR(ROUND(AVERAGEIFS(MASTER!$I:$I,MASTER!$B:$B,$A16),0),"-")) -> 5754 | H16: =IF($A16="","",IFERROR(_xlfn.MAXIFS(MASTER!$I:$I,MASTER!$B:$B,$A16),"-")) -> 12511 | I16: =IF($A16="","",IFERROR(IF(INDEX(MASTER!$I$4:$I$1463,MATCH($A16&"|"&ROUND($C16/2,0),MASTER!$Y$4:$Y$1463,0))="","-",INDEX(MASTER!$I$4:$I$1463,MATCH($A16&"|"&ROUND($C16/2,0),MASTER!$Y$4:$Y$1463,0))),"-")) -> 4939 | J16: =IF($A16="","",COUNTIFS(MASTER!$B:$B,$A16,MASTER!$I:$I,">=10000")) -> 12 | K16: =IF($A16="","",COUNTIFS(MASTER!$B:$B,$A16,MASTER!$I:$I,">=8000",MASTER!$I:$I,"<10000")) -> 11 | L16: =IF($A16="","",IFERROR(ROUND(AVERAGEIFS(MASTER!$L:$L,MASTER!$B:$B,$A16),1),"-")) -> 6.1 | M16: =IF($A16="","",IFERROR(ROUND(AVERAGEIFS(MASTER!$N:$N,MASTER!$B:$B,$A16),1),"-")) -> 55.6 | N16: =IF($A16="","",IFERROR(IF($A16="FUCT","- ours -",$G16-ROUND(AVERAGEIF(MASTER!$B:$B,"FUCT",MASTER!$I:$I),0)),"-")) -> 540 | O16: =IF(ISNUMBER($M16),RANK($M16,$M$11:$M$24),"-") -> 3 | P16: =IF($A16="","",IFERROR(IF(INDEX(MASTER!$C$4:$C$1463,MATCH($A16&"|1",MASTER!$Y$4:$Y$1463,0))="","-",INDEX(MASTER!$C$4:$C$1463,MATCH($A16&"|1",MASTER!$Y$4:$Y$1463,0))),"-")) -> AMBER | Q16: =IF($A16="","",IFERROR(IF(INDEX(MASTER!$I$4:$I$1463,MATCH($A16&"|1",MASTER!$Y$4:$Y$1463,0))="","-",INDEX(MASTER!$I$4:$I$1463,MATCH($A16&"|1",MASTER!$Y$4:$Y$1463,0))),"-")) -> 12511
A17: =IFERROR(INDEX(SETUP!$A$68:$A$81,MATCH(7,SETUP!$E$68:$E$81,0)),"") -> RECKONING | B17: =IF($A17="","",IFERROR(INDEX(SETUP!$B$68:$B$81,MATCH($A17,SETUP!$A$68:$A$81,0)),"-")) -> SHADOW | C17: =IF($A17="","",COUNTIF(MASTER!$B:$B,$A17)) -> 97 | D17: =IF($A17="","",COUNTIFS(MASTER!$B:$B,$A17,MASTER!$S:$S,"Complete")) -> 97 | E17: =IF($A17="","",IFERROR(ROUND(AVERAGEIFS(MASTER!$G:$G,MASTER!$B:$B,$A17),0),"-")) -> 62666 | F17: =IF($A17="","",IFERROR(_xlfn.MAXIFS(MASTER!$G:$G,MASTER!$B:$B,$A17),"-")) -> 64464 | G17: =IF($A17="","",IFERROR(ROUND(AVERAGEIFS(MASTER!$I:$I,MASTER!$B:$B,$A17),0),"-")) -> 5541 | H17: =IF($A17="","",IFERROR(_xlfn.MAXIFS(MASTER!$I:$I,MASTER!$B:$B,$A17),"-")) -> 11024 | I17: =IF($A17="","",IFERROR(IF(INDEX(MASTER!$I$4:$I$1463,MATCH($A17&"|"&ROUND($C17/2,0),MASTER!$Y$4:$Y$1463,0))="","-",INDEX(MASTER!$I$4:$I$1463,MATCH($A17&"|"&ROUND($C17/2,0),MASTER!$Y$4:$Y$1463,0))),"-")) -> 4850 | J17: =IF($A17="","",COUNTIFS(MASTER!$B:$B,$A17,MASTER!$I:$I,">=10000")) -> 9 | K17: =IF($A17="","",COUNTIFS(MASTER!$B:$B,$A17,MASTER!$I:$I,">=8000",MASTER!$I:$I,"<10000")) -> 12 | L17: =IF($A17="","",IFERROR(ROUND(AVERAGEIFS(MASTER!$L:$L,MASTER!$B:$B,$A17),1),"-")) -> 5.9 | M17: =IF($A17="","",IFERROR(ROUND(AVERAGEIFS(MASTER!$N:$N,MASTER!$B:$B,$A17),1),"-")) -> 54.2 | N17: =IF($A17="","",IFERROR(IF($A17="FUCT","- ours -",$G17-ROUND(AVERAGEIF(MASTER!$B:$B,"FUCT",MASTER!$I:$I),0)),"-")) -> 327 | O17: =IF(ISNUMBER($M17),RANK($M17,$M$11:$M$24),"-") -> 4 | P17: =IF($A17="","",IFERROR(IF(INDEX(MASTER!$C$4:$C$1463,MATCH($A17&"|1",MASTER!$Y$4:$Y$1463,0))="","-",INDEX(MASTER!$C$4:$C$1463,MATCH($A17&"|1",MASTER!$Y$4:$Y$1463,0))),"-")) -> Rydog | Q17: =IF($A17="","",IFERROR(IF(INDEX(MASTER!$I$4:$I$1463,MATCH($A17&"|1",MASTER!$Y$4:$Y$1463,0))="","-",INDEX(MASTER!$I$4:$I$1463,MATCH($A17&"|1",MASTER!$Y$4:$Y$1463,0))),"-")) -> 11024
A18: =IFERROR(INDEX(SETUP!$A$68:$A$81,MATCH(8,SETUP!$E$68:$E$81,0)),"") -> ACHERON | B18: =IF($A18="","",IFERROR(INDEX(SETUP!$B$68:$B$81,MATCH($A18,SETUP!$A$68:$A$81,0)),"-")) -> SHADOW | C18: =IF($A18="","",COUNTIF(MASTER!$B:$B,$A18)) -> 96 | D18: =IF($A18="","",COUNTIFS(MASTER!$B:$B,$A18,MASTER!$S:$S,"Complete")) -> 94 | E18: =IF($A18="","",IFERROR(ROUND(AVERAGEIFS(MASTER!$G:$G,MASTER!$B:$B,$A18),0),"-")) -> 62377 | F18: =IF($A18="","",IFERROR(_xlfn.MAXIFS(MASTER!$G:$G,MASTER!$B:$B,$A18),"-")) -> 64228 | G18: =IF($A18="","",IFERROR(ROUND(AVERAGEIFS(MASTER!$I:$I,MASTER!$B:$B,$A18),0),"-")) -> 4133 | H18: =IF($A18="","",IFERROR(_xlfn.MAXIFS(MASTER!$I:$I,MASTER!$B:$B,$A18),"-")) -> 10705 | I18: =IF($A18="","",IFERROR(IF(INDEX(MASTER!$I$4:$I$1463,MATCH($A18&"|"&ROUND($C18/2,0),MASTER!$Y$4:$Y$1463,0))="","-",INDEX(MASTER!$I$4:$I$1463,MATCH($A18&"|"&ROUND($C18/2,0),MASTER!$Y$4:$Y$1463,0))),"-")) -> 3863 | J18: =IF($A18="","",COUNTIFS(MASTER!$B:$B,$A18,MASTER!$I:$I,">=10000")) -> 1 | K18: =IF($A18="","",COUNTIFS(MASTER!$B:$B,$A18,MASTER!$I:$I,">=8000",MASTER!$I:$I,"<10000")) -> 5 | L18: =IF($A18="","",IFERROR(ROUND(AVERAGEIFS(MASTER!$L:$L,MASTER!$B:$B,$A18),1),"-")) -> 5.3 | M18: =IF($A18="","",IFERROR(ROUND(AVERAGEIFS(MASTER!$N:$N,MASTER!$B:$B,$A18),1),"-")) -> 46 | N18: =IF($A18="","",IFERROR(IF($A18="FUCT","- ours -",$G18-ROUND(AVERAGEIF(MASTER!$B:$B,"FUCT",MASTER!$I:$I),0)),"-")) -> -1081 | O18: =IF(ISNUMBER($M18),RANK($M18,$M$11:$M$24),"-") -> 8 | P18: =IF($A18="","",IFERROR(IF(INDEX(MASTER!$C$4:$C$1463,MATCH($A18&"|1",MASTER!$Y$4:$Y$1463,0))="","-",INDEX(MASTER!$C$4:$C$1463,MATCH($A18&"|1",MASTER!$Y$4:$Y$1463,0))),"-")) -> Sölus | Q18: =IF($A18="","",IFERROR(IF(INDEX(MASTER!$I$4:$I$1463,MATCH($A18&"|1",MASTER!$Y$4:$Y$1463,0))="","-",INDEX(MASTER!$I$4:$I$1463,MATCH($A18&"|1",MASTER!$Y$4:$Y$1463,0))),"-")) -> 10705
A19: =IFERROR(INDEX(SETUP!$A$68:$A$81,MATCH(9,SETUP!$E$68:$E$81,0)),"") -> INVICTUS | B19: =IF($A19="","",IFERROR(INDEX(SETUP!$B$68:$B$81,MATCH($A19,SETUP!$A$68:$A$81,0)),"-")) -> SHADOW | C19: =IF($A19="","",COUNTIF(MASTER!$B:$B,$A19)) -> 100 | D19: =IF($A19="","",COUNTIFS(MASTER!$B:$B,$A19,MASTER!$S:$S,"Complete")) -> 99 | E19: =IF($A19="","",IFERROR(ROUND(AVERAGEIFS(MASTER!$G:$G,MASTER!$B:$B,$A19),0),"-")) -> 61903 | F19: =IF($A19="","",IFERROR(_xlfn.MAXIFS(MASTER!$G:$G,MASTER!$B:$B,$A19),"-")) -> 64172 | G19: =IF($A19="","",IFERROR(ROUND(AVERAGEIFS(MASTER!$I:$I,MASTER!$B:$B,$A19),0),"-")) -> 3415 | H19: =IF($A19="","",IFERROR(_xlfn.MAXIFS(MASTER!$I:$I,MASTER!$B:$B,$A19),"-")) -> 9752 | I19: =IF($A19="","",IFERROR(IF(INDEX(MASTER!$I$4:$I$1463,MATCH($A19&"|"&ROUND($C19/2,0),MASTER!$Y$4:$Y$1463,0))="","-",INDEX(MASTER!$I$4:$I$1463,MATCH($A19&"|"&ROUND($C19/2,0),MASTER!$Y$4:$Y$1463,0))),"-")) -> 3040 | J19: =IF($A19="","",COUNTIFS(MASTER!$B:$B,$A19,MASTER!$I:$I,">=10000")) -> 0 | K19: =IF($A19="","",COUNTIFS(MASTER!$B:$B,$A19,MASTER!$I:$I,">=8000",MASTER!$I:$I,"<10000")) -> 3 | L19: =IF($A19="","",IFERROR(ROUND(AVERAGEIFS(MASTER!$L:$L,MASTER!$B:$B,$A19),1),"-")) -> 4.5 | M19: =IF($A19="","",IFERROR(ROUND(AVERAGEIFS(MASTER!$N:$N,MASTER!$B:$B,$A19),1),"-")) -> 40.6 | N19: =IF($A19="","",IFERROR(IF($A19="FUCT","- ours -",$G19-ROUND(AVERAGEIF(MASTER!$B:$B,"FUCT",MASTER!$I:$I),0)),"-")) -> -1799 | O19: =IF(ISNUMBER($M19),RANK($M19,$M$11:$M$24),"-") -> 10 | P19: =IF($A19="","",IFERROR(IF(INDEX(MASTER!$C$4:$C$1463,MATCH($A19&"|1",MASTER!$Y$4:$Y$1463,0))="","-",INDEX(MASTER!$C$4:$C$1463,MATCH($A19&"|1",MASTER!$Y$4:$Y$1463,0))),"-")) -> Seric | Q19: =IF($A19="","",IFERROR(IF(INDEX(MASTER!$I$4:$I$1463,MATCH($A19&"|1",MASTER!$Y$4:$Y$1463,0))="","-",INDEX(MASTER!$I$4:$I$1463,MATCH($A19&"|1",MASTER!$Y$4:$Y$1463,0))),"-")) -> 9752
A20: =IFERROR(INDEX(SETUP!$A$68:$A$81,MATCH(10,SETUP!$E$68:$E$81,0)),"") -> EMERALD LEAF TRIBE | B20: =IF($A20="","",IFERROR(INDEX(SETUP!$B$68:$B$81,MATCH($A20,SETUP!$A$68:$A$81,0)),"-")) -> SHADOW | C20: =IF($A20="","",COUNTIF(MASTER!$B:$B,$A20)) -> 97 | D20: =IF($A20="","",COUNTIFS(MASTER!$B:$B,$A20,MASTER!$S:$S,"Complete")) -> 97 | E20: =IF($A20="","",IFERROR(ROUND(AVERAGEIFS(MASTER!$G:$G,MASTER!$B:$B,$A20),0),"-")) -> 60411 | F20: =IF($A20="","",IFERROR(_xlfn.MAXIFS(MASTER!$G:$G,MASTER!$B:$B,$A20),"-")) -> 63451 | G20: =IF($A20="","",IFERROR(ROUND(AVERAGEIFS(MASTER!$I:$I,MASTER!$B:$B,$A20),0),"-")) -> 2318 | H20: =IF($A20="","",IFERROR(_xlfn.MAXIFS(MASTER!$I:$I,MASTER!$B:$B,$A20),"-")) -> 5260 | I20: =IF($A20="","",IFERROR(IF(INDEX(MASTER!$I$4:$I$1463,MATCH($A20&"|"&ROUND($C20/2,0),MASTER!$Y$4:$Y$1463,0))="","-",INDEX(MASTER!$I$4:$I$1463,MATCH($A20&"|"&ROUND($C20/2,0),MASTER!$Y$4:$Y$1463,0))),"-")) -> 2180 | J20: =IF($A20="","",COUNTIFS(MASTER!$B:$B,$A20,MASTER!$I:$I,">=10000")) -> 0 | K20: =IF($A20="","",COUNTIFS(MASTER!$B:$B,$A20,MASTER!$I:$I,">=8000",MASTER!$I:$I,"<10000")) -> 0 | L20: =IF($A20="","",IFERROR(ROUND(AVERAGEIFS(MASTER!$L:$L,MASTER!$B:$B,$A20),1),"-")) -> 3.7 | M20: =IF($A20="","",IFERROR(ROUND(AVERAGEIFS(MASTER!$N:$N,MASTER!$B:$B,$A20),1),"-")) -> 31.7 | N20: =IF($A20="","",IFERROR(IF($A20="FUCT","- ours -",$G20-ROUND(AVERAGEIF(MASTER!$B:$B,"FUCT",MASTER!$I:$I),0)),"-")) -> -2896 | O20: =IF(ISNUMBER($M20),RANK($M20,$M$11:$M$24),"-") -> 13 | P20: =IF($A20="","",IFERROR(IF(INDEX(MASTER!$C$4:$C$1463,MATCH($A20&"|1",MASTER!$Y$4:$Y$1463,0))="","-",INDEX(MASTER!$C$4:$C$1463,MATCH($A20&"|1",MASTER!$Y$4:$Y$1463,0))),"-")) -> Cal66 | Q20: =IF($A20="","",IFERROR(IF(INDEX(MASTER!$I$4:$I$1463,MATCH($A20&"|1",MASTER!$Y$4:$Y$1463,0))="","-",INDEX(MASTER!$I$4:$I$1463,MATCH($A20&"|1",MASTER!$Y$4:$Y$1463,0))),"-")) -> 5260
A21: =IFERROR(INDEX(SETUP!$A$68:$A$81,MATCH(11,SETUP!$E$68:$E$81,0)),"") -> SUB ROSA | B21: =IF($A21="","",IFERROR(INDEX(SETUP!$B$68:$B$81,MATCH($A21,SETUP!$A$68:$A$81,0)),"-")) -> SHADOW | C21: =IF($A21="","",COUNTIF(MASTER!$B:$B,$A21)) -> 93 | D21: =IF($A21="","",COUNTIFS(MASTER!$B:$B,$A21,MASTER!$S:$S,"Complete")) -> 68 | E21: =IF($A21="","",IFERROR(ROUND(AVERAGEIFS(MASTER!$G:$G,MASTER!$B:$B,$A21),0),"-")) -> 61588 | F21: =IF($A21="","",IFERROR(_xlfn.MAXIFS(MASTER!$G:$G,MASTER!$B:$B,$A21),"-")) -> 64435 | G21: =IF($A21="","",IFERROR(ROUND(AVERAGEIFS(MASTER!$I:$I,MASTER!$B:$B,$A21),0),"-")) -> 3056 | H21: =IF($A21="","",IFERROR(_xlfn.MAXIFS(MASTER!$I:$I,MASTER!$B:$B,$A21),"-")) -> 11094 | I21: =IF($A21="","",IFERROR(IF(INDEX(MASTER!$I$4:$I$1463,MATCH($A21&"|"&ROUND($C21/2,0),MASTER!$Y$4:$Y$1463,0))="","-",INDEX(MASTER!$I$4:$I$1463,MATCH($A21&"|"&ROUND($C21/2,0),MASTER!$Y$4:$Y$1463,0))),"-")) -> 1912 | J21: =IF($A21="","",COUNTIFS(MASTER!$B:$B,$A21,MASTER!$I:$I,">=10000")) -> 2 | K21: =IF($A21="","",COUNTIFS(MASTER!$B:$B,$A21,MASTER!$I:$I,">=8000",MASTER!$I:$I,"<10000")) -> 1 | L21: =IF($A21="","",IFERROR(ROUND(AVERAGEIFS(MASTER!$L:$L,MASTER!$B:$B,$A21),1),"-")) -> 4 | M21: =IF($A21="","",IFERROR(ROUND(AVERAGEIFS(MASTER!$N:$N,MASTER!$B:$B,$A21),1),"-")) -> 37.3 | N21: =IF($A21="","",IFERROR(IF($A21="FUCT","- ours -",$G21-ROUND(AVERAGEIF(MASTER!$B:$B,"FUCT",MASTER!$I:$I),0)),"-")) -> -2158 | O21: =IF(ISNUMBER($M21),RANK($M21,$M$11:$M$24),"-") -> 11 | P21: =IF($A21="","",IFERROR(IF(INDEX(MASTER!$C$4:$C$1463,MATCH($A21&"|1",MASTER!$Y$4:$Y$1463,0))="","-",INDEX(MASTER!$C$4:$C$1463,MATCH($A21&"|1",MASTER!$Y$4:$Y$1463,0))),"-")) -> Dwai | Q21: =IF($A21="","",IFERROR(IF(INDEX(MASTER!$I$4:$I$1463,MATCH($A21&"|1",MASTER!$Y$4:$Y$1463,0))="","-",INDEX(MASTER!$I$4:$I$1463,MATCH($A21&"|1",MASTER!$Y$4:$Y$1463,0))),"-")) -> 11094
A22: =IFERROR(INDEX(SETUP!$A$68:$A$81,MATCH(12,SETUP!$E$68:$E$81,0)),"") -> VENGEANCE | B22: =IF($A22="","",IFERROR(INDEX(SETUP!$B$68:$B$81,MATCH($A22,SETUP!$A$68:$A$81,0)),"-")) -> SHADOW | C22: =IF($A22="","",COUNTIF(MASTER!$B:$B,$A22)) -> 96 | D22: =IF($A22="","",COUNTIFS(MASTER!$B:$B,$A22,MASTER!$S:$S,"Complete")) -> 94 | E22: =IF($A22="","",IFERROR(ROUND(AVERAGEIFS(MASTER!$G:$G,MASTER!$B:$B,$A22),0),"-")) -> 61944 | F22: =IF($A22="","",IFERROR(_xlfn.MAXIFS(MASTER!$G:$G,MASTER!$B:$B,$A22),"-")) -> 63732 | G22: =IF($A22="","",IFERROR(ROUND(AVERAGEIFS(MASTER!$I:$I,MASTER!$B:$B,$A22),0),"-")) -> 3603 | H22: =IF($A22="","",IFERROR(_xlfn.MAXIFS(MASTER!$I:$I,MASTER!$B:$B,$A22),"-")) -> 7759 | I22: =IF($A22="","",IFERROR(IF(INDEX(MASTER!$I$4:$I$1463,MATCH($A22&"|"&ROUND($C22/2,0),MASTER!$Y$4:$Y$1463,0))="","-",INDEX(MASTER!$I$4:$I$1463,MATCH($A22&"|"&ROUND($C22/2,0),MASTER!$Y$4:$Y$1463,0))),"-")) -> 3408 | J22: =IF($A22="","",COUNTIFS(MASTER!$B:$B,$A22,MASTER!$I:$I,">=10000")) -> 0 | K22: =IF($A22="","",COUNTIFS(MASTER!$B:$B,$A22,MASTER!$I:$I,">=8000",MASTER!$I:$I,"<10000")) -> 0 | L22: =IF($A22="","",IFERROR(ROUND(AVERAGEIFS(MASTER!$L:$L,MASTER!$B:$B,$A22),1),"-")) -> 4.7 | M22: =IF($A22="","",IFERROR(ROUND(AVERAGEIFS(MASTER!$N:$N,MASTER!$B:$B,$A22),1),"-")) -> 41.9 | N22: =IF($A22="","",IFERROR(IF($A22="FUCT","- ours -",$G22-ROUND(AVERAGEIF(MASTER!$B:$B,"FUCT",MASTER!$I:$I),0)),"-")) -> -1611 | O22: =IF(ISNUMBER($M22),RANK($M22,$M$11:$M$24),"-") -> 9 | P22: =IF($A22="","",IFERROR(IF(INDEX(MASTER!$C$4:$C$1463,MATCH($A22&"|1",MASTER!$Y$4:$Y$1463,0))="","-",INDEX(MASTER!$C$4:$C$1463,MATCH($A22&"|1",MASTER!$Y$4:$Y$1463,0))),"-")) -> Stevo77 | Q22: =IF($A22="","",IFERROR(IF(INDEX(MASTER!$I$4:$I$1463,MATCH($A22&"|1",MASTER!$Y$4:$Y$1463,0))="","-",INDEX(MASTER!$I$4:$I$1463,MATCH($A22&"|1",MASTER!$Y$4:$Y$1463,0))),"-")) -> 7759
A23: =IFERROR(INDEX(SETUP!$A$68:$A$81,MATCH(13,SETUP!$E$68:$E$81,0)),"") -> VENDETTA | B23: =IF($A23="","",IFERROR(INDEX(SETUP!$B$68:$B$81,MATCH($A23,SETUP!$A$68:$A$81,0)),"-")) -> SHADOW | C23: =IF($A23="","",COUNTIF(MASTER!$B:$B,$A23)) -> 94 | D23: =IF($A23="","",COUNTIFS(MASTER!$B:$B,$A23,MASTER!$S:$S,"Complete")) -> 93 | E23: =IF($A23="","",IFERROR(ROUND(AVERAGEIFS(MASTER!$G:$G,MASTER!$B:$B,$A23),0),"-")) -> 61394 | F23: =IF($A23="","",IFERROR(_xlfn.MAXIFS(MASTER!$G:$G,MASTER!$B:$B,$A23),"-")) -> 63539 | G23: =IF($A23="","",IFERROR(ROUND(AVERAGEIFS(MASTER!$I:$I,MASTER!$B:$B,$A23),0),"-")) -> 2098 | H23: =IF($A23="","",IFERROR(_xlfn.MAXIFS(MASTER!$I:$I,MASTER!$B:$B,$A23),"-")) -> 4790 | I23: =IF($A23="","",IFERROR(IF(INDEX(MASTER!$I$4:$I$1463,MATCH($A23&"|"&ROUND($C23/2,0),MASTER!$Y$4:$Y$1463,0))="","-",INDEX(MASTER!$I$4:$I$1463,MATCH($A23&"|"&ROUND($C23/2,0),MASTER!$Y$4:$Y$1463,0))),"-")) -> 2030 | J23: =IF($A23="","",COUNTIFS(MASTER!$B:$B,$A23,MASTER!$I:$I,">=10000")) -> 0 | K23: =IF($A23="","",COUNTIFS(MASTER!$B:$B,$A23,MASTER!$I:$I,">=8000",MASTER!$I:$I,"<10000")) -> 0 | L23: =IF($A23="","",IFERROR(ROUND(AVERAGEIFS(MASTER!$L:$L,MASTER!$B:$B,$A23),1),"-")) -> 3.8 | M23: =IF($A23="","",IFERROR(ROUND(AVERAGEIFS(MASTER!$N:$N,MASTER!$B:$B,$A23),1),"-")) -> 32.3 | N23: =IF($A23="","",IFERROR(IF($A23="FUCT","- ours -",$G23-ROUND(AVERAGEIF(MASTER!$B:$B,"FUCT",MASTER!$I:$I),0)),"-")) -> -3116 | O23: =IF(ISNUMBER($M23),RANK($M23,$M$11:$M$24),"-") -> 12 | P23: =IF($A23="","",IFERROR(IF(INDEX(MASTER!$C$4:$C$1463,MATCH($A23&"|1",MASTER!$Y$4:$Y$1463,0))="","-",INDEX(MASTER!$C$4:$C$1463,MATCH($A23&"|1",MASTER!$Y$4:$Y$1463,0))),"-")) -> anamal | Q23: =IF($A23="","",IFERROR(IF(INDEX(MASTER!$I$4:$I$1463,MATCH($A23&"|1",MASTER!$Y$4:$Y$1463,0))="","-",INDEX(MASTER!$I$4:$I$1463,MATCH($A23&"|1",MASTER!$Y$4:$Y$1463,0))),"-")) -> 4790
A24: =IFERROR(INDEX(SETUP!$A$68:$A$81,MATCH(14,SETUP!$E$68:$E$81,0)),"") -> ZOMBIES | B24: =IF($A24="","",IFERROR(INDEX(SETUP!$B$68:$B$81,MATCH($A24,SETUP!$A$68:$A$81,0)),"-")) -> SHADOW | C24: =IF($A24="","",COUNTIF(MASTER!$B:$B,$A24)) -> 98 | D24: =IF($A24="","",COUNTIFS(MASTER!$B:$B,$A24,MASTER!$S:$S,"Complete")) -> 97 | E24: =IF($A24="","",IFERROR(ROUND(AVERAGEIFS(MASTER!$G:$G,MASTER!$B:$B,$A24),0),"-")) -> 60959 | F24: =IF($A24="","",IFERROR(_xlfn.MAXIFS(MASTER!$G:$G,MASTER!$B:$B,$A24),"-")) -> 63698 | G24: =IF($A24="","",IFERROR(ROUND(AVERAGEIFS(MASTER!$I:$I,MASTER!$B:$B,$A24),0),"-")) -> 2100 | H24: =IF($A24="","",IFERROR(_xlfn.MAXIFS(MASTER!$I:$I,MASTER!$B:$B,$A24),"-")) -> 8652 | I24: =IF($A24="","",IFERROR(IF(INDEX(MASTER!$I$4:$I$1463,MATCH($A24&"|"&ROUND($C24/2,0),MASTER!$Y$4:$Y$1463,0))="","-",INDEX(MASTER!$I$4:$I$1463,MATCH($A24&"|"&ROUND($C24/2,0),MASTER!$Y$4:$Y$1463,0))),"-")) -> 1740 | J24: =IF($A24="","",COUNTIFS(MASTER!$B:$B,$A24,MASTER!$I:$I,">=10000")) -> 0 | K24: =IF($A24="","",COUNTIFS(MASTER!$B:$B,$A24,MASTER!$I:$I,">=8000",MASTER!$I:$I,"<10000")) -> 2 | L24: =IF($A24="","",IFERROR(ROUND(AVERAGEIFS(MASTER!$L:$L,MASTER!$B:$B,$A24),1),"-")) -> 3.7 | M24: =IF($A24="","",IFERROR(ROUND(AVERAGEIFS(MASTER!$N:$N,MASTER!$B:$B,$A24),1),"-")) -> 31 | N24: =IF($A24="","",IFERROR(IF($A24="FUCT","- ours -",$G24-ROUND(AVERAGEIF(MASTER!$B:$B,"FUCT",MASTER!$I:$I),0)),"-")) -> -3114 | O24: =IF(ISNUMBER($M24),RANK($M24,$M$11:$M$24),"-") -> 14 | P24: =IF($A24="","",IFERROR(IF(INDEX(MASTER!$C$4:$C$1463,MATCH($A24&"|1",MASTER!$Y$4:$Y$1463,0))="","-",INDEX(MASTER!$C$4:$C$1463,MATCH($A24&"|1",MASTER!$Y$4:$Y$1463,0))),"-")) -> THERIDDIC | Q24: =IF($A24="","",IFERROR(IF(INDEX(MASTER!$I$4:$I$1463,MATCH($A24&"|1",MASTER!$Y$4:$Y$1463,0))="","-",INDEX(MASTER!$I$4:$I$1463,MATCH($A24&"|1",MASTER!$Y$4:$Y$1463,0))),"-")) -> 8652
A26: ROSTER BY RESONANCE TIER · in view | H26: ROSTER BY CLASS · in view
A27: Tier | B27: Players | C27: Share | D27: FUCT | E27: Avg CR | F27: Shape | H27: Class | I27: Role | J27: Players | K27: FUCT | L27: Avg reso | M27: Shape
A28: =SETUP!$B$22 -> MYTHIC | B28: =SUMPRODUCT((MASTER!$J$4:$J$1463=$A28)*(IF($C$3="ALL",1,MASTER!$A$4:$A$1463=$C$3))) -> 3 | C28: =IFERROR($B28/SUM($B$28:$B$34),"") -> 0.0022641509 | D28: =COUNTIFS(MASTER!$B:$B,"FUCT",MASTER!$J:$J,$A28) -> 0 | E28: =IFERROR(ROUND(AVERAGEIFS(MASTER!$G:$G,MASTER!$J:$J,$A28),0),"-") -> 64241 | F28: =REPT("|",ROUND($B28/6,0)) -> | | H28: BARBARIAN | I28: =IFERROR(INDEX(SETUP!$B$55:$B$64,MATCH($H28,SETUP!$A$55:$A$64,0)),"-") -> Frontline | J28: =SUMPRODUCT((MASTER!$E$4:$E$1463=$H28)*(IF($C$3="ALL",1,MASTER!$A$4:$A$1463=$C$3))) -> 214 | K28: =COUNTIFS(MASTER!$B:$B,"FUCT",MASTER!$E:$E,$H28) -> 19 | L28: =IFERROR(ROUND(AVERAGEIFS(MASTER!$I:$I,MASTER!$E:$E,$H28),0),"-") -> 4743 | M28: =REPT("|",ROUND($J28/6,0)) -> ||||||||||||||||||||||||||||||||||||
A29: =SETUP!$B$21 -> APEX | B29: =SUMPRODUCT((MASTER!$J$4:$J$1463=$A29)*(IF($C$3="ALL",1,MASTER!$A$4:$A$1463=$C$3))) -> 52 | C29: =IFERROR($B29/SUM($B$28:$B$34),"") -> 0.039245283 | D29: =COUNTIFS(MASTER!$B:$B,"FUCT",MASTER!$J:$J,$A29) -> 5 | E29: =IFERROR(ROUND(AVERAGEIFS(MASTER!$G:$G,MASTER!$J:$J,$A29),0),"-") -> 64034 | F29: =REPT("|",ROUND($B29/6,0)) -> ||||||||| | H29: BLOOD KNIGHT | I29: =IFERROR(INDEX(SETUP!$B$55:$B$64,MATCH($H29,SETUP!$A$55:$A$64,0)),"-") -> Frontline | J29: =SUMPRODUCT((MASTER!$E$4:$E$1463=$H29)*(IF($C$3="ALL",1,MASTER!$A$4:$A$1463=$C$3))) -> 93 | K29: =COUNTIFS(MASTER!$B:$B,"FUCT",MASTER!$E:$E,$H29) -> 7 | L29: =IFERROR(ROUND(AVERAGEIFS(MASTER!$I:$I,MASTER!$E:$E,$H29),0),"-") -> 4134 | M29: =REPT("|",ROUND($J29/6,0)) -> ||||||||||||||||
A30: =SETUP!$B$20 -> ELITE | B30: =SUMPRODUCT((MASTER!$J$4:$J$1463=$A30)*(IF($C$3="ALL",1,MASTER!$A$4:$A$1463=$C$3))) -> 94 | C30: =IFERROR($B30/SUM($B$28:$B$34),"") -> 0.070943396 | D30: =COUNTIFS(MASTER!$B:$B,"FUCT",MASTER!$J:$J,$A30) -> 9 | E30: =IFERROR(ROUND(AVERAGEIFS(MASTER!$G:$G,MASTER!$J:$J,$A30),0),"-") -> 63555 | F30: =REPT("|",ROUND($B30/6,0)) -> |||||||||||||||| | H30: CRUSADER | I30: =IFERROR(INDEX(SETUP!$B$55:$B$64,MATCH($H30,SETUP!$A$55:$A$64,0)),"-") -> Frontline | J30: =SUMPRODUCT((MASTER!$E$4:$E$1463=$H30)*(IF($C$3="ALL",1,MASTER!$A$4:$A$1463=$C$3))) -> 124 | K30: =COUNTIFS(MASTER!$B:$B,"FUCT",MASTER!$E:$E,$H30) -> 7 | L30: =IFERROR(ROUND(AVERAGEIFS(MASTER!$I:$I,MASTER!$E:$E,$H30),0),"-") -> 5072 | M30: =REPT("|",ROUND($J30/6,0)) -> |||||||||||||||||||||
A31: =SETUP!$B$19 -> VETERAN | B31: =SUMPRODUCT((MASTER!$J$4:$J$1463=$A31)*(IF($C$3="ALL",1,MASTER!$A$4:$A$1463=$C$3))) -> 139 | C31: =IFERROR($B31/SUM($B$28:$B$34),"") -> 0.10490566 | D31: =COUNTIFS(MASTER!$B:$B,"FUCT",MASTER!$J:$J,$A31) -> 14 | E31: =IFERROR(ROUND(AVERAGEIFS(MASTER!$G:$G,MASTER!$J:$J,$A31),0),"-") -> 62985 | F31: =REPT("|",ROUND($B31/6,0)) -> ||||||||||||||||||||||| | H31: DEMON HUNTER | I31: =IFERROR(INDEX(SETUP!$B$55:$B$64,MATCH($H31,SETUP!$A$55:$A$64,0)),"-") -> Ranged DPS | J31: =SUMPRODUCT((MASTER!$E$4:$E$1463=$H31)*(IF($C$3="ALL",1,MASTER!$A$4:$A$1463=$C$3))) -> 191 | K31: =COUNTIFS(MASTER!$B:$B,"FUCT",MASTER!$E:$E,$H31) -> 18 | L31: =IFERROR(ROUND(AVERAGEIFS(MASTER!$I:$I,MASTER!$E:$E,$H31),0),"-") -> 4661 | M31: =REPT("|",ROUND($J31/6,0)) -> ||||||||||||||||||||||||||||||||
A32: =SETUP!$B$18 -> CORE | B32: =SUMPRODUCT((MASTER!$J$4:$J$1463=$A32)*(IF($C$3="ALL",1,MASTER!$A$4:$A$1463=$C$3))) -> 317 | C32: =IFERROR($B32/SUM($B$28:$B$34),"") -> 0.23924528 | D32: =COUNTIFS(MASTER!$B:$B,"FUCT",MASTER!$J:$J,$A32) -> 33 | E32: =IFERROR(ROUND(AVERAGEIFS(MASTER!$G:$G,MASTER!$J:$J,$A32),0),"-") -> 62705 | F32: =REPT("|",ROUND($B32/6,0)) -> ||||||||||||||||||||||||||||||||||||||||||||||||||||| | H32: DRUID | I32: =IFERROR(INDEX(SETUP!$B$55:$B$64,MATCH($H32,SETUP!$A$55:$A$64,0)),"-") -> Support | J32: =SUMPRODUCT((MASTER!$E$4:$E$1463=$H32)*(IF($C$3="ALL",1,MASTER!$A$4:$A$1463=$C$3))) -> 71 | K32: =COUNTIFS(MASTER!$B:$B,"FUCT",MASTER!$E:$E,$H32) -> 5 | L32: =IFERROR(ROUND(AVERAGEIFS(MASTER!$I:$I,MASTER!$E:$E,$H32),0),"-") -> 3918 | M32: =REPT("|",ROUND($J32/6,0)) -> ||||||||||||
A33: =SETUP!$B$17 -> DEVELOPING | B33: =SUMPRODUCT((MASTER!$J$4:$J$1463=$A33)*(IF($C$3="ALL",1,MASTER!$A$4:$A$1463=$C$3))) -> 512 | C33: =IFERROR($B33/SUM($B$28:$B$34),"") -> 0.38641509 | D33: =COUNTIFS(MASTER!$B:$B,"FUCT",MASTER!$J:$J,$A33) -> 38 | E33: =IFERROR(ROUND(AVERAGEIFS(MASTER!$G:$G,MASTER!$J:$J,$A33),0),"-") -> 61930 | F33: =REPT("|",ROUND($B33/6,0)) -> ||||||||||||||||||||||||||||||||||||||||||||||||||||||||||||||||||||||||||||||||||||| | H33: MONK | I33: =IFERROR(INDEX(SETUP!$B$55:$B$64,MATCH($H33,SETUP!$A$55:$A$64,0)),"-") -> Support | J33: =SUMPRODUCT((MASTER!$E$4:$E$1463=$H33)*(IF($C$3="ALL",1,MASTER!$A$4:$A$1463=$C$3))) -> 39 | K33: =COUNTIFS(MASTER!$B:$B,"FUCT",MASTER!$E:$E,$H33) -> 3 | L33: =IFERROR(ROUND(AVERAGEIFS(MASTER!$I:$I,MASTER!$E:$E,$H33),0),"-") -> 4780 | M33: =REPT("|",ROUND($J33/6,0)) -> |||||||
A34: =SETUP!$B$16 -> ROOKIE | B34: =SUMPRODUCT((MASTER!$J$4:$J$1463=$A34)*(IF($C$3="ALL",1,MASTER!$A$4:$A$1463=$C$3))) -> 208 | C34: =IFERROR($B34/SUM($B$28:$B$34),"") -> 0.15698113 | D34: =COUNTIFS(MASTER!$B:$B,"FUCT",MASTER!$J:$J,$A34) -> 0 | E34: =IFERROR(ROUND(AVERAGEIFS(MASTER!$G:$G,MASTER!$J:$J,$A34),0),"-") -> 60277 | F34: =REPT("|",ROUND($B34/6,0)) -> ||||||||||||||||||||||||||||||||||| | H34: NECROMANCER | I34: =IFERROR(INDEX(SETUP!$B$55:$B$64,MATCH($H34,SETUP!$A$55:$A$64,0)),"-") -> Control | J34: =SUMPRODUCT((MASTER!$E$4:$E$1463=$H34)*(IF($C$3="ALL",1,MASTER!$A$4:$A$1463=$C$3))) -> 108 | K34: =COUNTIFS(MASTER!$B:$B,"FUCT",MASTER!$E:$E,$H34) -> 6 | L34: =IFERROR(ROUND(AVERAGEIFS(MASTER!$I:$I,MASTER!$E:$E,$H34),0),"-") -> 3198 | M34: =REPT("|",ROUND($J34/6,0)) -> ||||||||||||||||||
H35: TEMPEST | I35: =IFERROR(INDEX(SETUP!$B$55:$B$64,MATCH($H35,SETUP!$A$55:$A$64,0)),"-") -> Melee DPS | J35: =SUMPRODUCT((MASTER!$E$4:$E$1463=$H35)*(IF($C$3="ALL",1,MASTER!$A$4:$A$1463=$C$3))) -> 67 | K35: =COUNTIFS(MASTER!$B:$B,"FUCT",MASTER!$E:$E,$H35) -> 6 | L35: =IFERROR(ROUND(AVERAGEIFS(MASTER!$I:$I,MASTER!$E:$E,$H35),0),"-") -> 3546 | M35: =REPT("|",ROUND($J35/6,0)) -> |||||||||||
H36: WARLOCK | I36: =IFERROR(INDEX(SETUP!$B$55:$B$64,MATCH($H36,SETUP!$A$55:$A$64,0)),"-") -> Control | J36: =SUMPRODUCT((MASTER!$E$4:$E$1463=$H36)*(IF($C$3="ALL",1,MASTER!$A$4:$A$1463=$C$3))) -> 326 | K36: =COUNTIFS(MASTER!$B:$B,"FUCT",MASTER!$E:$E,$H36) -> 17 | L36: =IFERROR(ROUND(AVERAGEIFS(MASTER!$I:$I,MASTER!$E:$E,$H36),0),"-") -> 4200 | M36: =REPT("|",ROUND($J36/6,0)) -> ||||||||||||||||||||||||||||||||||||||||||||||||||||||
H37: WIZARD | I37: =IFERROR(INDEX(SETUP!$B$55:$B$64,MATCH($H37,SETUP!$A$55:$A$64,0)),"-") -> Ranged DPS | J37: =SUMPRODUCT((MASTER!$E$4:$E$1463=$H37)*(IF($C$3="ALL",1,MASTER!$A$4:$A$1463=$C$3))) -> 92 | K37: =COUNTIFS(MASTER!$B:$B,"FUCT",MASTER!$E:$E,$H37) -> 11 | L37: =IFERROR(ROUND(AVERAGEIFS(MASTER!$I:$I,MASTER!$E:$E,$H37),0),"-") -> 4306 | M37: =REPT("|",ROUND($J37/6,0)) -> |||||||||||||||

Sheet DEPTH CURVES
A1: DEPTH CURVES · where FUCT is stronger and weaker than everyone else
A2: Pick a stat and a rival. Each line runs from a clan's strongest player to its weakest, so the same point on the axis is a like-for-like slot.
A4: STAT > | B4: RESONANCE | D4: RIVAL > | E4: UNDYING | H4: =IF($B$4="RESONANCE","Resonance — the headline number.",IF($B$4="COMBAT RATING","Combat Rating — gear and paragon floor. Note the whole field sits in a narrow 55k-64.5k band.","Secondary average, in thousands — armor / pen / potency / resist.")) -> Resonance — the headline number.
A6: THE PICTURE | Q6: KEY
Q7: FUCT — us
Q8: =$E$4 -> UNDYING
Q9: every other clan
Q11: Left edge = each clan's best player.
Q12: Right edge = each clan's weakest.
Q13: Halfway across = their median.
Q14: Rosters differ in size, so the axis is
Q15: share of roster, not headcount — that
Q16: keeps a 93-man clan comparable to a 102.
A36: PERCENTILE TABLE · the same story in numbers, for the stat selected above
A37: Clan | B37: Faction | C37: Top 5 avg | D37: 10th | E37: 25th | F37: Median | G37: 75th | H37: vs FUCT median
A38: FUCT | B38: STANDALONE | C38: =IFERROR(ROUND(AVERAGE(IF($B$4="RESONANCE",IFERROR(IF(INDEX(MASTER!$I$4:$I$1463,MATCH($A38&"|"&1,MASTER!$Y$4:$Y$1463,0))="","",INDEX(MASTER!$I$4:$I$1463,MATCH($A38&"|"&1,MASTER!$Y$4:$Y$1463,0))),""),IF($B$4="COMBAT RATING",IFERROR(IF(INDEX(MASTER!$G$4:$G$1463,MATCH($A38&"|"&1,MASTER!$AH$4:$AH$1463,0))="","",INDEX(MASTER!$G$4:$G$1463,MATCH($A38&"|"&1,MASTER!$AH$4:$AH$1463,0))),""),IF($B$4="SECONDARY",IFERROR(IF(INDEX(MASTER!$L$4:$L$1463,MATCH($A38&"|"&1,MASTER!$AI$4:$AI$1463,0))="","",INDEX(MASTER!$L$4:$L$1463,MATCH($A38&"|"&1,MASTER!$AI$4:$AI$1463,0))),"")))),IF($B$4="RESONANCE",IFERROR(IF(INDEX(MASTER!$I$4:$I$1463,MATCH($A38&"|"&2,MASTER!$Y$4:$Y$1463,0))="","",INDEX(MASTER!$I$4:$I$1463,MATCH($A38&"|"&2,MASTER!$Y$4:$Y$1463,0))),""),IF($B$4="COMBAT RATING",IFERROR(IF(INDEX(MASTER!$G$4:$G$1463,MATCH($A38&"|"&2,MASTER!$AH$4:$AH$1463,0))="","",INDEX(MASTER!$G$4:$G$1463,MATCH($A38&"|"&2,MASTER!$AH$4:$AH$1463,0))),""),IF($B$4="SECONDARY",IFERROR(IF(INDEX(MASTER!$L$4:$L$1463,MATCH($A38&"|"&2,MASTER!$AI$4:$AI$1463,0))="","",INDEX(MASTER!$L$4:$L$1463,MATCH($A38&"|"&2,MASTER!$AI$4:$AI$1463,0))),"")))),IF($B$4="RESONANCE",IFERROR(IF(INDEX(MASTER!$I$4:$I$1463,MATCH($A38&"|"&3,MASTER!$Y$4:$Y$1463,0))="","",INDEX(MASTER!$I$4:$I$1463,MATCH($A38&"|"&3,MASTER!$Y$4:$Y$1463,0))),""),IF($B$4="COMBAT RATING",IFERROR(IF(INDEX(MASTER!$G$4:$G$1463,MATCH($A38&"|"&3,MASTER!$AH$4:$AH$1463,0))="","",INDEX(MASTER!$G$4:$G$1463,MATCH($A38&"|"&3,MASTER!$AH$4:$AH$1463,0))),""),IF($B$4="SECONDARY",IFERROR(IF(INDEX(MASTER!$L$4:$L$1463,MATCH($A38&"|"&3,MASTER!$AI$4:$AI$1463,0))="","",INDEX(MASTER!$L$4:$L$1463,MATCH($A38&"|"&3,MASTER!$AI$4:$AI$1463,0))),"")))),IF($B$4="RESONANCE",IFERROR(IF(INDEX(MASTER!$I$4:$I$1463,MATCH($A38&"|"&4,MASTER!$Y$4:$Y$1463,0))="","",INDEX(MASTER!$I$4:$I$1463,MATCH($A38&"|"&4,MASTER!$Y$4:$Y$1463,0))),""),IF($B$4="COMBAT RATING",IFERROR(IF(INDEX(MASTER!$G$4:$G$1463,MATCH($A38&"|"&4,MASTER!$AH$4:$AH$1463,0))="","",INDEX(MASTER!$G$4:$G$1463,MATCH($A38&"|"&4,MASTER!$AH$4:$AH$1463,0))),""),IF($B$4="SECONDARY",IFERROR(IF(INDEX(MASTER!$L$4:$L$1463,MATCH($A38&"|"&4,MASTER!$AI$4:$AI$1463,0))="","",INDEX(MASTER!$L$4:$L$1463,MATCH($A38&"|"&4,MASTER!$AI$4:$AI$1463,0))),"")))),IF($B$4="RESONANCE",IFERROR(IF(INDEX(MASTER!$I$4:$I$1463,MATCH($A38&"|"&5,MASTER!$Y$4:$Y$1463,0))="","",INDEX(MASTER!$I$4:$I$1463,MATCH($A38&"|"&5,MASTER!$Y$4:$Y$1463,0))),""),IF($B$4="COMBAT RATING",IFERROR(IF(INDEX(MASTER!$G$4:$G$1463,MATCH($A38&"|"&5,MASTER!$AH$4:$AH$1463,0))="","",INDEX(MASTER!$G$4:$G$1463,MATCH($A38&"|"&5,MASTER!$AH$4:$AH$1463,0))),""),IF($B$4="SECONDARY",IFERROR(IF(INDEX(MASTER!$L$4:$L$1463,MATCH($A38&"|"&5,MASTER!$AI$4:$AI$1463,0))="","",INDEX(MASTER!$L$4:$L$1463,MATCH($A38&"|"&5,MASTER!$AI$4:$AI$1463,0))),""))))),1),"-") -> 10482 | D38: =IFERROR(ROUND(IF($B$4="RESONANCE",IFERROR(IF(INDEX(MASTER!$I$4:$I$1463,MATCH($A38&"|"&MAX(1,ROUND(COUNTIFS(MASTER!$B:$B,$A38,MASTER!$S:$S,"<>Name only")*0.1,0)),MASTER!$Y$4:$Y$1463,0))="","",INDEX(MASTER!$I$4:$I$1463,MATCH($A38&"|"&MAX(1,ROUND(COUNTIFS(MASTER!$B:$B,$A38,MASTER!$S:$S,"<>Name only")*0.1,0)),MASTER!$Y$4:$Y$1463,0))),""),IF($B$4="COMBAT RATING",IFERROR(IF(INDEX(MASTER!$G$4:$G$1463,MATCH($A38&"|"&MAX(1,ROUND(COUNTIFS(MASTER!$B:$B,$A38,MASTER!$S:$S,"<>Name only")*0.1,0)),MASTER!$AH$4:$AH$1463,0))="","",INDEX(MASTER!$G$4:$G$1463,MATCH($A38&"|"&MAX(1,ROUND(COUNTIFS(MASTER!$B:$B,$A38,MASTER!$S:$S,"<>Name only")*0.1,0)),MASTER!$AH$4:$AH$1463,0))),""),IF($B$4="SECONDARY",IFERROR(IF(INDEX(MASTER!$L$4:$L$1463,MATCH($A38&"|"&MAX(1,ROUND(COUNTIFS(MASTER!$B:$B,$A38,MASTER!$S:$S,"<>Name only")*0.1,0)),MASTER!$AI$4:$AI$1463,0))="","",INDEX(MASTER!$L$4:$L$1463,MATCH($A38&"|"&MAX(1,ROUND(COUNTIFS(MASTER!$B:$B,$A38,MASTER!$S:$S,"<>Name only")*0.1,0)),MASTER!$AI$4:$AI$1463,0))),"")))),1),"-") -> 8529 | E38: =IFERROR(ROUND(IF($B$4="RESONANCE",IFERROR(IF(INDEX(MASTER!$I$4:$I$1463,MATCH($A38&"|"&MAX(1,ROUND(COUNTIFS(MASTER!$B:$B,$A38,MASTER!$S:$S,"<>Name only")*0.25,0)),MASTER!$Y$4:$Y$1463,0))="","",INDEX(MASTER!$I$4:$I$1463,MATCH($A38&"|"&MAX(1,ROUND(COUNTIFS(MASTER!$B:$B,$A38,MASTER!$S:$S,"<>Name only")*0.25,0)),MASTER!$Y$4:$Y$1463,0))),""),IF($B$4="COMBAT RATING",IFERROR(IF(INDEX(MASTER!$G$4:$G$1463,MATCH($A38&"|"&MAX(1,ROUND(COUNTIFS(MASTER!$B:$B,$A38,MASTER!$S:$S,"<>Name only")*0.25,0)),MASTER!$AH$4:$AH$1463,0))="","",INDEX(MASTER!$G$4:$G$1463,MATCH($A38&"|"&MAX(1,ROUND(COUNTIFS(MASTER!$B:$B,$A38,MASTER!$S:$S,"<>Name only")*0.25,0)),MASTER!$AH$4:$AH$1463,0))),""),IF($B$4="SECONDARY",IFERROR(IF(INDEX(MASTER!$L$4:$L$1463,MATCH($A38&"|"&MAX(1,ROUND(COUNTIFS(MASTER!$B:$B,$A38,MASTER!$S:$S,"<>Name only")*0.25,0)),MASTER!$AI$4:$AI$1463,0))="","",INDEX(MASTER!$L$4:$L$1463,MATCH($A38&"|"&MAX(1,ROUND(COUNTIFS(MASTER!$B:$B,$A38,MASTER!$S:$S,"<>Name only")*0.25,0)),MASTER!$AI$4:$AI$1463,0))),"")))),1),"-") -> 6573 | F38: =IFERROR(ROUND(IF($B$4="RESONANCE",IFERROR(IF(INDEX(MASTER!$I$4:$I$1463,MATCH($A38&"|"&MAX(1,ROUND(COUNTIFS(MASTER!$B:$B,$A38,MASTER!$S:$S,"<>Name only")*0.5,0)),MASTER!$Y$4:$Y$1463,0))="","",INDEX(MASTER!$I$4:$I$1463,MATCH($A38&"|"&MAX(1,ROUND(COUNTIFS(MASTER!$B:$B,$A38,MASTER!$S:$S,"<>Name only")*0.5,0)),MASTER!$Y$4:$Y$1463,0))),""),IF($B$4="COMBAT RATING",IFERROR(IF(INDEX(MASTER!$G$4:$G$1463,MATCH($A38&"|"&MAX(1,ROUND(COUNTIFS(MASTER!$B:$B,$A38,MASTER!$S:$S,"<>Name only")*0.5,0)),MASTER!$AH$4:$AH$1463,0))="","",INDEX(MASTER!$G$4:$G$1463,MATCH($A38&"|"&MAX(1,ROUND(COUNTIFS(MASTER!$B:$B,$A38,MASTER!$S:$S,"<>Name only")*0.5,0)),MASTER!$AH$4:$AH$1463,0))),""),IF($B$4="SECONDARY",IFERROR(IF(INDEX(MASTER!$L$4:$L$1463,MATCH($A38&"|"&MAX(1,ROUND(COUNTIFS(MASTER!$B:$B,$A38,MASTER!$S:$S,"<>Name only")*0.5,0)),MASTER!$AI$4:$AI$1463,0))="","",INDEX(MASTER!$L$4:$L$1463,MATCH($A38&"|"&MAX(1,ROUND(COUNTIFS(MASTER!$B:$B,$A38,MASTER!$S:$S,"<>Name only")*0.5,0)),MASTER!$AI$4:$AI$1463,0))),"")))),1),"-") -> 4435 | G38: =IFERROR(ROUND(IF($B$4="RESONANCE",IFERROR(IF(INDEX(MASTER!$I$4:$I$1463,MATCH($A38&"|"&MAX(1,ROUND(COUNTIFS(MASTER!$B:$B,$A38,MASTER!$S:$S,"<>Name only")*0.75,0)),MASTER!$Y$4:$Y$1463,0))="","",INDEX(MASTER!$I$4:$I$1463,MATCH($A38&"|"&MAX(1,ROUND(COUNTIFS(MASTER!$B:$B,$A38,MASTER!$S:$S,"<>Name only")*0.75,0)),MASTER!$Y$4:$Y$1463,0))),""),IF($B$4="COMBAT RATING",IFERROR(IF(INDEX(MASTER!$G$4:$G$1463,MATCH($A38&"|"&MAX(1,ROUND(COUNTIFS(MASTER!$B:$B,$A38,MASTER!$S:$S,"<>Name only")*0.75,0)),MASTER!$AH$4:$AH$1463,0))="","",INDEX(MASTER!$G$4:$G$1463,MATCH($A38&"|"&MAX(1,ROUND(COUNTIFS(MASTER!$B:$B,$A38,MASTER!$S:$S,"<>Name only")*0.75,0)),MASTER!$AH$4:$AH$1463,0))),""),IF($B$4="SECONDARY",IFERROR(IF(INDEX(MASTER!$L$4:$L$1463,MATCH($A38&"|"&MAX(1,ROUND(COUNTIFS(MASTER!$B:$B,$A38,MASTER!$S:$S,"<>Name only")*0.75,0)),MASTER!$AI$4:$AI$1463,0))="","",INDEX(MASTER!$L$4:$L$1463,MATCH($A38&"|"&MAX(1,ROUND(COUNTIFS(MASTER!$B:$B,$A38,MASTER!$S:$S,"<>Name only")*0.75,0)),MASTER!$AI$4:$AI$1463,0))),"")))),1),"-") -> 3498 | H38: =IFERROR(IF($A38="FUCT","- ours -",ROUND($F38-INDEX($F$38:$F$51,MATCH("FUCT",$A$38:$A$51,0)),1)),"-") -> - ours -
